<?xml version="1.0" encoding="utf-8"?>
<!-- =================================================================================== -->
<!-- |    This document was autogenerated by xacro from q_dot_02.xacro                 | -->
<!-- |    EDITING THIS FILE BY HAND IS NOT RECOMMENDED                                 | -->
<!-- =================================================================================== -->
<robot name="q_dot_02">
  <material name="silver">
    <color rgba="0.700 0.700 0.700 1.000"/>
  </material>
  <transmission name="rf_hip_joint_tran">
    <type>transmission_interface/SimpleTransmission</type>
    <joint name="rf_hip_joint">
      <hardwareInterface>hardware_interface/EffortJointInterface</hardwareInterface>
    </joint>
    <actuator name="rf_hip_joint_actr">
      <hardwareInterface>hardware_interface/EffortJointInterface</hardwareInterface>
      <mechanicalReduction>1</mechanicalReduction>
    </actuator>
  </transmission>
  <transmission name="lf_hip_joint_tran">
    <type>transmission_interface/SimpleTransmission</type>
    <joint name="lf_hip_joint">
      <hardwareInterface>hardware_interface/EffortJointInterface</hardwareInterface>
    </joint>
    <actuator name="lf_hip_joint_actr">
      <hardwareInterface>hardware_interface/EffortJointInterface</hardwareInterface>
      <mechanicalReduction>1</mechanicalReduction>
    </actuator>
  </transmission>
  <transmission name="lh_hip_joint_tran">
    <type>transmission_interface/SimpleTransmission</type>
    <joint name="lh_hip_joint">
      <hardwareInterface>hardware_interface/EffortJointInterface</hardwareInterface>
    </joint>
    <actuator name="lh_hip_joint_actr">
      <hardwareInterface>hardware_interface/EffortJointInterface</hardwareInterface>
      <mechanicalReduction>1</mechanicalReduction>
    </actuator>
  </transmission>
  <transmission name="rh_hip_joint_tran">
    <type>transmission_interface/SimpleTransmission</type>
    <joint name="rh_hip_joint">
      <hardwareInterface>hardware_interface/EffortJointInterface</hardwareInterface>
    </joint>
    <actuator name="rh_hip_joint_actr">
      <hardwareInterface>hardware_interface/EffortJointInterface</hardwareInterface>
      <mechanicalReduction>1</mechanicalReduction>
    </actuator>
  </transmission>
  <transmission name="rf_upper_joint_tran">
    <type>transmission_interface/SimpleTransmission</type>
    <joint name="rf_upper_joint">
      <hardwareInterface>hardware_interface/EffortJointInterface</hardwareInterface>
    </joint>
    <actuator name="rf_upper_joint_actr">
      <hardwareInterface>hardware_interface/EffortJointInterface</hardwareInterface>
      <mechanicalReduction>1</mechanicalReduction>
    </actuator>
  </transmission>
  <transmission name="rf_lower_joint_tran">
    <type>transmission_interface/SimpleTransmission</type>
    <joint name="rf_lower_joint">
      <hardwareInterface>hardware_interface/EffortJointInterface</hardwareInterface>
    </joint>
    <actuator name="rf_lower_joint_actr">
      <hardwareInterface>hardware_interface/EffortJointInterface</hardwareInterface>
      <mechanicalReduction>1</mechanicalReduction>
    </actuator>
  </transmission>
  <transmission name="lf_upper_joint_tran">
    <type>transmission_interface/SimpleTransmission</type>
    <joint name="lf_upper_joint">
      <hardwareInterface>hardware_interface/EffortJointInterface</hardwareInterface>
    </joint>
    <actuator name="lf_upper_joint_actr">
      <hardwareInterface>hardware_interface/EffortJointInterface</hardwareInterface>
      <mechanicalReduction>1</mechanicalReduction>
    </actuator>
  </transmission>
  <transmission name="lf_lower_joint_tran">
    <type>transmission_interface/SimpleTransmission</type>
    <joint name="lf_lower_joint">
      <hardwareInterface>hardware_interface/EffortJointInterface</hardwareInterface>
    </joint>
    <actuator name="lf_lower_joint_actr">
      <hardwareInterface>hardware_interface/EffortJointInterface</hardwareInterface>
      <mechanicalReduction>1</mechanicalReduction>
    </actuator>
  </transmission>
  <transmission name="lh_upper_joint_tran">
    <type>transmission_interface/SimpleTransmission</type>
    <joint name="lh_upper_joint">
      <hardwareInterface>hardware_interface/EffortJointInterface</hardwareInterface>
    </joint>
    <actuator name="lh_upper_joint_actr">
      <hardwareInterface>hardware_interface/EffortJointInterface</hardwareInterface>
      <mechanicalReduction>1</mechanicalReduction>
    </actuator>
  </transmission>
  <transmission name="lh_lower_joint_tran">
    <type>transmission_interface/SimpleTransmission</type>
    <joint name="lh_lower_joint">
      <hardwareInterface>hardware_interface/EffortJointInterface</hardwareInterface>
    </joint>
    <actuator name="lh_lower_joint_actr">
      <hardwareInterface>hardware_interface/EffortJointInterface</hardwareInterface>
      <mechanicalReduction>1</mechanicalReduction>
    </actuator>
  </transmission>
  <transmission name="rh_upper_joint_tran">
    <type>transmission_interface/SimpleTransmission</type>
    <joint name="rh_upper_joint">
      <hardwareInterface>hardware_interface/EffortJointInterface</hardwareInterface>
    </joint>
    <actuator name="rh_upper_joint_actr">
      <hardwareInterface>hardware_interface/EffortJointInterface</hardwareInterface>
      <mechanicalReduction>1</mechanicalReduction>
    </actuator>
  </transmission>
  <transmission name="rh_lower_joint_tran">
    <type>transmission_interface/SimpleTransmission</type>
    <joint name="rh_lower_joint">
      <hardwareInterface>hardware_interface/EffortJointInterface</hardwareInterface>
    </joint>
    <actuator name="rh_lower_joint_actr">
      <hardwareInterface>hardware_interface/EffortJointInterface</hardwareInterface>
      <mechanicalReduction>1</mechanicalReduction>
    </actuator>
  </transmission>
  <gazebo>
    <plugin filename="libgazebo_ros_control.so" name="control"/>
  </gazebo>
  <gazebo reference="base_link">
    <material>Gazebo/Silver</material>
    <mu1>0.2</mu1>
    <mu2>0.2</mu2>
    <selfCollide>true</selfCollide>
    <gravity>true</gravity>
  </gazebo>
  <gazebo reference="rf_hip_link_1">
    <material>Gazebo/Silver</material>
    <mu1>0.2</mu1>
    <mu2>0.2</mu2>
    <selfCollide>true</selfCollide>
  </gazebo>
  <gazebo reference="lf_hip_link_1">
    <material>Gazebo/Silver</material>
    <mu1>0.2</mu1>
    <mu2>0.2</mu2>
    <selfCollide>true</selfCollide>
  </gazebo>
  <gazebo reference="lh_hip_link_1">
    <material>Gazebo/Silver</material>
    <mu1>0.2</mu1>
    <mu2>0.2</mu2>
    <selfCollide>true</selfCollide>
  </gazebo>
  <gazebo reference="rh_hip_link_1">
    <material>Gazebo/Silver</material>
    <mu1>0.2</mu1>
    <mu2>0.2</mu2>
    <selfCollide>true</selfCollide>
  </gazebo>
  <gazebo reference="rf_upper_leg_link_1">
    <material>Gazebo/Silver</material>
    <mu1>0.2</mu1>
    <mu2>0.2</mu2>
    <selfCollide>true</selfCollide>
  </gazebo>
  <gazebo reference="rf_lower_leg_link_1">
    <material>Gazebo/Silver</material>
    <mu1>0.2</mu1>
    <mu2>0.2</mu2>
    <selfCollide>true</selfCollide>
  </gazebo>
  <gazebo reference="lf_upper_leg_link_1">
    <material>Gazebo/Silver</material>
    <mu1>0.2</mu1>
    <mu2>0.2</mu2>
    <selfCollide>true</selfCollide>
  </gazebo>
  <gazebo reference="lf_lower_leg_link_1">
    <material>Gazebo/Silver</material>
    <mu1>0.2</mu1>
    <mu2>0.2</mu2>
    <selfCollide>true</selfCollide>
  </gazebo>
  <gazebo reference="lh_upper_leg_link_1">
    <material>Gazebo/Silver</material>
    <mu1>0.2</mu1>
    <mu2>0.2</mu2>
    <selfCollide>true</selfCollide>
  </gazebo>
  <gazebo reference="lh_lower_leg_link_1">
    <material>Gazebo/Silver</material>
    <mu1>0.2</mu1>
    <mu2>0.2</mu2>
    <selfCollide>true</selfCollide>
  </gazebo>
  <gazebo reference="rh_upper_leg_link_1">
    <material>Gazebo/Silver</material>
    <mu1>0.2</mu1>
    <mu2>0.2</mu2>
    <selfCollide>true</selfCollide>
  </gazebo>
  <gazebo reference="rh_lower_leg_link_1">
    <material>Gazebo/Silver</material>
    <mu1>0.2</mu1>
    <mu2>0.2</mu2>
    <selfCollide>true</selfCollide>
  </gazebo>
  <link name="base_link">
    <inertial>
      <origin rpy="0 0 0" xyz="-3.749856284860472e-06 -9.02420120018054e-18 -1.093119461551725e-06"/>
      <mass value="0.9889425737724369"/>
      <inertia ixx="0.000371" ixy="-0.0" ixz="0.0" iyy="0.000478" iyz="-0.0" izz="0.0007"/>
    </inertial>
    <visual>
      <origin rpy="0 0 0" xyz="0 0 0"/>
      <geometry>
        <mesh filename="package://q_dot_02_description/meshes/base_link.stl" scale="0.001 0.001 0.001"/>
      </geometry>
      <material name="silver"/>
    </visual>
    <collision>
      <origin rpy="0 0 0" xyz="0 0 0"/>
      <geometry>
        <mesh filename="package://q_dot_02_description/meshes/base_link.stl" scale="0.001 0.001 0.001"/>
      </geometry>
    </collision>
  </link>
  <link name="rf_hip_link_1">
    <inertial>
      <origin rpy="0 0 0" xyz="0.015001687347942105 1.734723475976807e-17 0.0"/>
      <mass value="0.21192533849766937"/>
      <inertia ixx="3.2e-05" ixy="0.0" ixz="0.0" iyy="3.2e-05" iyz="0.0" izz="3.2e-05"/>
    </inertial>
    <visual>
      <origin rpy="0 0 0" xyz="-0.035 0.03 -0.0"/>
      <geometry>
        <mesh filename="package://q_dot_02_description/meshes/rf_hip_link_1.stl" scale="0.001 0.001 0.001"/>
      </geometry>
      <material name="silver"/>
    </visual>
    <collision>
      <origin rpy="0 0 0" xyz="-0.035 0.03 -0.0"/>
      <geometry>
        <mesh filename="package://q_dot_02_description/meshes/rf_hip_link_1.stl" scale="0.001 0.001 0.001"/>
      </geometry>
    </collision>
  </link>
  <link name="lf_hip_link_1">
    <inertial>
      <origin rpy="0 0 0" xyz="0.015001687347942098 1.734723475976807e-17 -2.6319460028976815e-18"/>
      <mass value="0.2119253384976692"/>
      <inertia ixx="3.2e-05" ixy="0.0" ixz="-0.0" iyy="3.2e-05" iyz="-0.0" izz="3.2e-05"/>
    </inertial>
    <visual>
      <origin rpy="0 0 0" xyz="-0.035 -0.03 -0.0"/>
      <geometry>
        <mesh filename="package://q_dot_02_description/meshes/lf_hip_link_1.stl" scale="0.001 0.001 0.001"/>
      </geometry>
      <material name="silver"/>
    </visual>
    <collision>
      <origin rpy="0 0 0" xyz="-0.035 -0.03 -0.0"/>
      <geometry>
        <mesh filename="package://q_dot_02_description/meshes/lf_hip_link_1.stl" scale="0.001 0.001 0.001"/>
      </geometry>
    </collision>
  </link>
  <link name="lh_hip_link_1">
    <inertial>
      <origin rpy="0 0 0" xyz="-0.015001687347942105 -2.42861286636753e-17 3.469446951953614e-18"/>
      <mass value="0.2119253384976694"/>
      <inertia ixx="3.2e-05" ixy="0.0" ixz="0.0" iyy="3.2e-05" iyz="0.0" izz="3.2e-05"/>
    </inertial>
    <visual>
      <origin rpy="0 0 0" xyz="0.035 -0.03 0.001"/>
      <geometry>
        <mesh filename="package://q_dot_02_description/meshes/lh_hip_link_1.stl" scale="0.001 0.001 0.001"/>
      </geometry>
      <material name="silver"/>
    </visual>
    <collision>
      <origin rpy="0 0 0" xyz="0.035 -0.03 0.001"/>
      <geometry>
        <mesh filename="package://q_dot_02_description/meshes/lh_hip_link_1.stl" scale="0.001 0.001 0.001"/>
      </geometry>
    </collision>
  </link>
  <link name="rh_hip_link_1">
    <inertial>
      <origin rpy="0 0 0" xyz="-0.015001687347942105 -1.734723475976807e-17 0.0"/>
      <mass value="0.21192533849766917"/>
      <inertia ixx="3.2e-05" ixy="0.0" ixz="-0.0" iyy="3.2e-05" iyz="-0.0" izz="3.2e-05"/>
    </inertial>
    <visual>
      <origin rpy="0 0 0" xyz="0.035 0.03 -0.0"/>
      <geometry>
        <mesh filename="package://q_dot_02_description/meshes/rh_hip_link_1.stl" scale="0.001 0.001 0.001"/>
      </geometry>
      <material name="silver"/>
    </visual>
    <collision>
      <origin rpy="0 0 0" xyz="0.035 0.03 -0.0"/>
      <geometry>
        <mesh filename="package://q_dot_02_description/meshes/rh_hip_link_1.stl" scale="0.001 0.001 0.001"/>
      </geometry>
    </collision>
  </link>
  <link name="rf_upper_leg_link_1">
    <inertial>
      <origin rpy="0 0 0" xyz="0.0 -0.0025000000000000022 -0.015060554087736015"/>
      <mass value="0.03370014250693511"/>
      <inertia ixx="7e-06" ixy="-0.0" ixz="-0.0" iyy="8e-06" iyz="-0.0" izz="1e-06"/>
    </inertial>
    <visual>
      <origin rpy="0 0 0" xyz="-0.05 0.045 -0.0"/>
      <geometry>
        <mesh filename="package://q_dot_02_description/meshes/rf_upper_leg_link_1.stl" scale="0.001 0.001 0.001"/>
      </geometry>
      <material name="silver"/>
    </visual>
    <collision>
      <origin rpy="0 0 0" xyz="-0.05 0.045 -0.0"/>
      <geometry>
        <mesh filename="package://q_dot_02_description/meshes/rf_upper_leg_link_1.stl" scale="0.001 0.001 0.001"/>
      </geometry>
    </collision>
  </link>
  <link name="rf_lower_leg_link_1">
    <inertial>
      <origin rpy="0 0 0" xyz="0.0 -0.0024999999999999953 -0.01706099375174222"/>
      <mass value="0.02467231228210367"/>
      <inertia ixx="5e-06" ixy="0.0" ixz="0.0" iyy="5e-06" iyz="0.0" izz="0.0"/>
    </inertial>
    <visual>
      <origin rpy="0 0 0" xyz="-0.05 0.05 0.035"/>
      <geometry>
        <mesh filename="package://q_dot_02_description/meshes/rf_lower_leg_link_1.stl" scale="0.001 0.001 0.001"/>
      </geometry>
      <material name="silver"/>
    </visual>
    <collision>
      <origin rpy="0 0 0" xyz="-0.05 0.05 0.035"/>
      <geometry>
        <mesh filename="package://q_dot_02_description/meshes/rf_lower_leg_link_1.stl" scale="0.001 0.001 0.001"/>
      </geometry>
    </collision>
  </link>
  <!-- RF FOOT -->
  <link name="rf_foot_link"/>
  <!-- RF FOOT -->
  <link name="lf_upper_leg_link_1">
    <inertial>
      <origin rpy="0 0 0" xyz="0.0 0.002500000000000009 -0.015060554087736"/>
      <mass value="0.033700142506935094"/>
      <inertia ixx="7e-06" ixy="0.0" ixz="-0.0" iyy="8e-06" iyz="0.0" izz="1e-06"/>
    </inertial>
    <visual>
      <origin rpy="0 0 0" xyz="-0.05 -0.045 -0.0"/>
      <geometry>
        <mesh filename="package://q_dot_02_description/meshes/lf_upper_leg_link_1.stl" scale="0.001 0.001 0.001"/>
      </geometry>
      <material name="silver"/>
    </visual>
    <collision>
      <origin rpy="0 0 0" xyz="-0.05 -0.045 -0.0"/>
      <geometry>
        <mesh filename="package://q_dot_02_description/meshes/lf_upper_leg_link_1.stl" scale="0.001 0.001 0.001"/>
      </geometry>
    </collision>
  </link>
  <link name="lf_lower_leg_link_1">
    <inertial>
      <origin rpy="0 0 0" xyz="-2.0816681711721685e-17 0.002500000000000009 -0.017060993751742214"/>
      <mass value="0.024672312282103682"/>
      <inertia ixx="5e-06" ixy="0.0" ixz="0.0" iyy="5e-06" iyz="-0.0" izz="0.0"/>
    </inertial>
    <visual>
      <origin rpy="0 0 0" xyz="-0.05 -0.05 0.035"/>
      <geometry>
        <mesh filename="package://q_dot_02_description/meshes/lf_lower_leg_link_1.stl" scale="0.001 0.001 0.001"/>
      </geometry>
      <material name="silver"/>
    </visual>
    <collision>
      <origin rpy="0 0 0" xyz="-0.05 -0.05 0.035"/>
      <geometry>
        <mesh filename="package://q_dot_02_description/meshes/lf_lower_leg_link_1.stl" scale="0.001 0.001 0.001"/>
      </geometry>
    </collision>
  </link>
  <!-- LF FOOT -->
  <link name="lf_foot_link"/>
  <!-- LF FOOT -->
  <link name="lh_upper_leg_link_1">
    <inertial>
      <origin rpy="0 0 0" xyz="-3.469446951953614e-17 0.0024999999999999953 -0.015060554087736003"/>
      <mass value="0.0337001425069351"/>
      <inertia ixx="7e-06" ixy="-0.0" ixz="0.0" iyy="8e-06" iyz="0.0" izz="1e-06"/>
    </inertial>
    <visual>
      <origin rpy="0 0 0" xyz="0.05 -0.045 0.001"/>
      <geometry>
        <mesh filename="package://q_dot_02_description/meshes/lh_upper_leg_link_1.stl" scale="0.001 0.001 0.001"/>
      </geometry>
      <material name="silver"/>
    </visual>
    <collision>
      <origin rpy="0 0 0" xyz="0.05 -0.045 0.001"/>
      <geometry>
        <mesh filename="package://q_dot_02_description/meshes/lh_upper_leg_link_1.stl" scale="0.001 0.001 0.001"/>
      </geometry>
    </collision>
  </link>
  <link name="lh_lower_leg_link_1">
    <inertial>
      <origin rpy="0 0 0" xyz="-2.0816681711721685e-17 0.0024999999999999883 -0.0170609937517422"/>
      <mass value="0.02467231228210367"/>
      <inertia ixx="5e-06" ixy="0.0" ixz="-0.0" iyy="5e-06" iyz="0.0" izz="0.0"/>
    </inertial>
    <visual>
      <origin rpy="0 0 0" xyz="0.05 -0.05 0.036"/>
      <geometry>
        <mesh filename="package://q_dot_02_description/meshes/lh_lower_leg_link_1.stl" scale="0.001 0.001 0.001"/>
      </geometry>
      <material name="silver"/>
    </visual>
    <collision>
      <origin rpy="0 0 0" xyz="0.05 -0.05 0.036"/>
      <geometry>
        <mesh filename="package://q_dot_02_description/meshes/lh_lower_leg_link_1.stl" scale="0.001 0.001 0.001"/>
      </geometry>
    </collision>
  </link>
  <!-- LH FOOT -->
  <link name="lh_foot_link"/>
  <!-- LH FOOT -->
  <link name="rh_upper_leg_link_1">
    <inertial>
      <origin rpy="0 0 0" xyz="1.3877787807814457e-17 -0.002500000000000009 -0.015060554087736015"/>
      <mass value="0.03370014250693509"/>
      <inertia ixx="7e-06" ixy="-0.0" ixz="0.0" iyy="8e-06" iyz="0.0" izz="1e-06"/>
    </inertial>
    <visual>
      <origin rpy="0 0 0" xyz="0.05 0.045 -0.0"/>
      <geometry>
        <mesh filename="package://q_dot_02_description/meshes/rh_upper_leg_link_1.stl" scale="0.001 0.001 0.001"/>
      </geometry>
      <material name="silver"/>
    </visual>
    <collision>
      <origin rpy="0 0 0" xyz="0.05 0.045 -0.0"/>
      <geometry>
        <mesh filename="package://q_dot_02_description/meshes/rh_upper_leg_link_1.stl" scale="0.001 0.001 0.001"/>
      </geometry>
    </collision>
  </link>
  <link name="rh_lower_leg_link_1">
    <inertial>
      <origin rpy="0 0 0" xyz="2.7755575615628914e-17 -0.002500000000000009 -0.01706099375174224"/>
      <mass value="0.024672312282103703"/>
      <inertia ixx="5e-06" ixy="-0.0" ixz="0.0" iyy="5e-06" iyz="0.0" izz="0.0"/>
    </inertial>
    <visual>
      <origin rpy="0 0 0" xyz="0.05 0.05 0.035"/>
      <geometry>
        <mesh filename="package://q_dot_02_description/meshes/rh_lower_leg_link_1.stl" scale="0.001 0.001 0.001"/>
      </geometry>
      <material name="silver"/>
    </visual>
    <collision>
      <origin rpy="0 0 0" xyz="0.05 0.05 0.035"/>
      <geometry>
        <mesh filename="package://q_dot_02_description/meshes/rh_lower_leg_link_1.stl" scale="0.001 0.001 0.001"/>
      </geometry>
    </collision>
  </link>
  <!-- RH FOOT -->
  <link name="rh_foot_link"/>
  <!-- RH FOOT -->
  <!-- JOINTS -->
  <joint name="rf_hip_joint" type="continuous">
    <origin rpy="0 0 0" xyz="0.035 -0.03 0.0"/>
    <parent link="base_link"/>
    <child link="rf_hip_link_1"/>
    <axis xyz="1.0 0.0 0.0"/>
  </joint>
  <joint name="lf_hip_joint" type="continuous">
    <origin rpy="0 0 0" xyz="0.035 0.03 0.0"/>
    <parent link="base_link"/>
    <child link="lf_hip_link_1"/>
    <axis xyz="1.0 0.0 0.0"/>
  </joint>
  <joint name="lh_hip_joint" type="continuous">
    <origin rpy="0 0 0" xyz="-0.035 0.03 -0.001"/>
    <parent link="base_link"/>
    <child link="lh_hip_link_1"/>
    <axis xyz="1.0 0.0 0.0"/>
  </joint>
  <joint name="rh_hip_joint" type="continuous">
    <origin rpy="0 0 0" xyz="-0.035 -0.03 0.0"/>
    <parent link="base_link"/>
    <child link="rh_hip_link_1"/>
    <axis xyz="1.0 0.0 0.0"/>
  </joint>
  <joint name="rf_upper_joint" type="continuous">
    <origin rpy="0 0 0" xyz="0.015 -0.015 0.0"/>
    <parent link="rf_hip_link_1"/>
    <child link="rf_upper_leg_link_1"/>
    <axis xyz="0.0 1.0 0.0"/>
  </joint>
  <joint name="rf_lower_joint" type="continuous">
    <origin rpy="0 0 0" xyz="0.0 -0.005 -0.035"/>
    <parent link="rf_upper_leg_link_1"/>
    <child link="rf_lower_leg_link_1"/>
    <axis xyz="0.0 1.0 0.0"/>
  </joint>
  <!-- RF JOINT -->
  <joint name="rf_foot_joint" type="fixed">
    <origin rpy="0 0 0" xyz="0.0 0.0 -0.045"/>
    <parent link="rf_lower_leg_link_1"/>
    <child link="rf_foot_link"/>
  </joint>
  <!-- RF JOINT -->
  <joint name="lf_upper_joint" type="continuous">
    <origin rpy="0 0 0" xyz="0.015 0.015 0.0"/>
    <parent link="lf_hip_link_1"/>
    <child link="lf_upper_leg_link_1"/>
    <axis xyz="-0.0 1.0 0.0"/>
  </joint>
  <joint name="lf_lower_joint" type="continuous">
    <origin rpy="0 0 0" xyz="0.0 0.005 -0.035"/>
    <parent link="lf_upper_leg_link_1"/>
    <child link="lf_lower_leg_link_1"/>
    <axis xyz="-0.0 1.0 0.0"/>
  </joint>
  <!-- LF JOINT -->
  <joint name="lf_foot_joint" type="fixed">
    <origin rpy="0 0 0" xyz="0.0 0.0 -0.045"/>
    <parent link="lf_lower_leg_link_1"/>
    <child link="lf_foot_link"/>
  </joint>
  <!-- LF JOINT -->
  <joint name="lh_upper_joint" type="continuous">
    <origin rpy="0 0 0" xyz="-0.015 0.015 0.0"/>
    <parent link="lh_hip_link_1"/>
    <child link="lh_upper_leg_link_1"/>
    <axis xyz="-0.0 1.0 0.0"/>
  </joint>
  <joint name="lh_lower_joint" type="continuous">
    <origin rpy="0 0 0" xyz="0.0 0.005 -0.035"/>
    <parent link="lh_upper_leg_link_1"/>
    <child link="lh_lower_leg_link_1"/>
    <axis xyz="-0.0 1.0 0.0"/>
  </joint>
  <!-- LH JOINT -->
  <joint name="lh_foot_joint" type="fixed">
    <origin rpy="0 0 0" xyz="0.0 0.0 -0.045"/>
    <parent link="lh_lower_leg_link_1"/>
    <child link="lh_foot_link"/>
  </joint>
  <!-- LH JOINT -->
  <joint name="rh_upper_joint" type="continuous">
    <origin rpy="0 0 0" xyz="-0.015 -0.015 0.0"/>
    <parent link="rh_hip_link_1"/>
    <child link="rh_upper_leg_link_1"/>
    <axis xyz="0.0 1.0 0.0"/>
  </joint>
  <joint name="rh_lower_joint" type="continuous">
    <origin rpy="0 0 0" xyz="0.0 -0.005 -0.035"/>
    <parent link="rh_upper_leg_link_1"/>
    <child link="rh_lower_leg_link_1"/>
    <axis xyz="0.0 1.0 0.0"/>
  </joint>
  <!-- RH JOINT -->
  <joint name="rh_foot_joint" type="fixed">
    <origin rpy="0 0 0" xyz="0.0 0.0 -0.045"/>
    <parent link="rh_lower_leg_link_1"/>
    <child link="rh_foot_link"/>
  </joint>
  <!-- RH JOINT -->
</robot>

